Workbook

Sheet README
B2: Riverbend Food Bank — Donor & Volunteer CRM Workbook
B3: A donor/volunteer data cleaning, analysis, and engagement-tracking project
B4: Tip: jump straight to the Engagement_Dashboard tab for the executive-summary view, or follow the tabs in order to see the full data-cleaning process.
B6: Purpose
B7: Many small nonprofits track donors and volunteers in spreadsheets, not dedicated CRM software. This workbook shows how a messy donor export and a volunteer sign-up log can be cleaned, linked, and turned into decision-useful summaries — without buying a CRM platform.
B8: Data sources
B9: Donor demographics and giving history are adapted from a real, anonymized university fundraising dataset (Kaggle: 'Fundraising Data' by Michael Pawlus), re-labeled for a food bank context. The Raw_Outreach tab uses the real, anonymized donor contact reports from the same dataset. The Volunteers tab is synthetic data generated to mirror realistic shift/hours patterns, linked to roughly 120 of the donor records to model people who both give and volunteer.
B10: How this workbook is organized
B11: Raw_Donors / Raw_Volunteers / Raw_Outreach
B12: Unedited data as it would arrive from an export. Intentionally messy: inconsistent text casing, trailing whitespace, duplicate records, currency stored as text, missing values.
B13: Clean_Donors / Clean_Volunteers
B14: Cleaned versions built with formulas (TRIM, UPPER/PROPER, VALUE, IFERROR, COUNTIF for duplicate flags) so the cleaning logic is visible and auditable, not just pasted-over values.
... B21: Donor identities, addresses, and amounts in the donor and outreach tabs are anonymized/synthetic data from a public dataset and do not represent a real food bank's actual donors.

Sheet Raw_Donors
A1: DonorID | B1: ZIP Code | C1: Age | D1: Marital Status | E1: Gender | F1: Donor Category | G1: Volunteer Engaged | H1: Wealth Rating | I1: Preferred Contact Type | J1: Email on File | K1: Consecutive Years Giving | L1: Giving FY2021 | M1: Giving FY2022 | N1: Giving FY2023 | O1: Giving FY2024 | P1: Giving FY2025 | Q1: Total Lifetime Giving | R1: Is Donor | S1: Birth Date
A2: D1000 | B2: 46743 | E2: Female | F2: Individual Donor | G2: N | I2: HOME | J2: N | K2: 1 | L2: $0 | M2: $0 | N2: $0 | O2: $0 | P2: $0 | Q2: 0 | R2: N
A3: D1001 | B3: 27054 | E3: Male | F3: Family Donor | G3: N | I3: BUSN | J3: Y | K3: 0 | L3: $0 | M3: $0 | N3: $0 | O3: $0 | P3: $0 | Q3: 334 | R3: Y
A4: D1002 | B4: 45843 | E4: Male | F4: Individual Donor | G4: N | I4: HOME | J4: N | K4: 1 | L4: $0 | M4: $0 | N4: $0 | O4: $0 | P4: $0 | Q4: 870 | R4: Y
A5: D1003 | B5: 33953 | E5: Uknown | F5: Individual Donor | G5: N | I5: HOME | J5: N | K5: 0 | L5: $0 | M5: $0 | N5: $0 | O5: $0 | P5: $0 | Q5: 0 | R5: N
A6: D1004 | B6: 63013 | C6: 39 | E6: Female | F6: Individual Donor | G6: N | I6: HOME | J6: N | K6: 0 | L6: $0 | M6: $0 | N6: $0 | O6: $0 | P6: $0 | Q6: 490 | R6: Y | S6: 1978-05-22
A7: D1005 | B7: 41832 | C7: 55 | E7: Male | F7: Community Partner | G7: N | I7: HOME | J7: N | K7: 1 | L7: $0 | M7: $0 | N7: $0 | O7: $0 | P7: $0 | Q7: 0 | R7: N | S7: 1962-01-21
A8: D1006 | B8: 35402 | E8: Male | F8: Individual Donor | G8: Y | I8: HOME | J8: N | K8: 0 | L8: $0 | M8: $0 | N8: $0 | O8: $0 | P8: $1 | Q8: 50 | R8: Y
A9: D1007 | B9: 25714 | C9: 23 | E9: Female | F9: Individual Donor | G9: N | I9: HOME | J9: N | K9: 0 | L9: $0 | M9: $0 | N9: $0 | O9: $0 | P9: $0 | Q9: 1000 | R9: Y | S9: 1994-05-13
A10: D1008 | B10: 71635 | E10: Male | F10: Individual Donor | G10: N | I10: HOME | J10: N | K10: 1 | L10: $0 | M10: $0 | N10: $0 | O10: $0 | P10: $0 | Q10: 0 | R10: N
A11: D1009 | B11: 29062 | D11: Married | E11: Male | F11: Individual Donor | G11: N | I11: HOME | J11: Y | K11: 1 | L11: $0 | M11: $0 | N11: $0 | O11: $0 | P11: $100 | Q11: 100 | R11: Y
A12: D1010 | B12: 40224 | E12: Male | F12: Individual Donor | G12: N | I12: HOME | J12: N | K12: 1 | L12: $0 | M12: $0 | N12: $0 | O12: $0 | P12: $0 | Q12: 0 | R12: N
A13: D1011 | B13: 5481 | E13: Male | F13: Community Partner | G13: Y | I13: HOME | J13: Y | K13: 3 | L13: $0 | M13: $0 | N13: $0 | O13: $0 | P13: $0 | Q13: 0 | R13: N
A14: D1012 | B14: 11366 | C14: 74 | E14: Male | F14: Individual Donor | G14: N | I14: HOME | J14: N | K14: 0 | L14: $0 | M14: $0 | N14: $0 | O14: $0 | P14: $1 | Q14: 81 | R14: Y | S14: 1943-05-23
A15: D1013 | B15: 1106 | C15: 26 | E15: Female | F15: Individual Donor | G15: N | I15: HOME | J15: N | K15: 0 | L15: $0 | M15: $0 | N15: $0 | O15: $0 | P15: $0 | Q15: 40 | R15: Y | S15: 1991-12-13
A16: D1014 | B16: 7720 | C16: 50 | E16: Female | F16: Community Partner | G16: Y | I16: HOME | J16: Y | K16: 1 | L16: $0 | M16: $0 | N16: $0 | O16: $25 | P16: $0 | Q16: 25 | R16: Y | S16: 1967-09-01
A17: D1015 | B17: 17864 | D17: Married | E17: Male | F17: Individual Donor | G17: N | I17: HOME | J17: Y | K17: 0 | L17: $0 | M17: $0 | N17: $0 | O17: $0 | P17: $0 | Q17: 300 | R17: Y
A18: D1016 | B18: 96809 | C18: 26 | E18: Female | F18: Community Partner | G18: Y | I18: HOME | J18: Y | K18: 2 | L18: $0 | M18: $0 | N18: $0 | O18: $0 | P18: $0 | Q18: 3000 | R18: Y | S18: 1991-03-19
A19: D1017 | B19: 40355 | D19: Married | E19: Female | F19: Individual Donor | G19: Y | I19: HOME | J19: Y | K19: 4 | L19: $400 | M19: $0 | N19: $0 | O19: $0 | P19: $0 | Q19: 400 | R19: Y
A20: D1018 | B20: 36275 | D20: Divorced | E20: Male | F20: Family Donor | G20: N | H20: $1-$24,999 | I20: HOME | J20: Y | K20: 0 | L20: $0 | M20: $0 | N20: $0 | O20: $0 | P20: $0 | Q20: 120 | R20: Y
A21: D1019 | B21: 90302 | D21: Single | E21: Male | F21: Individual Donor | G21: N | J21: Y | K21: 0 | L21: $0 | M21: $0 | N21: $0 | O21: $0 | P21: $0 | Q21: 0 | R21: N
A22: D1020 | B22: 32420 | E22: Female | F22: Community Partner | G22: N | I22: HOME | J22: Y | K22: 0 | L22: $0 | M22: $0 | N22: $0 | O22: $0 | P22: $0 | Q22: 0 | R22: N
A23: D1021 | B23: 90265 | E23: Male | F23: Individual Donor | G23: N | J23: N | K23: 1 | L23: $0 | M23: $0 | N23: $136 | O23: $200 | P23: $0 | Q23: 2375 | R23: Y
A24: D1022 | E24: Male | F24: Individual Donor | G24: N | J24: N | K24: 1 | L24: $0 | M24: $50 | N24: $1 | O24: $251 | P24: $0 | Q24: 870 | R24: Y
A25: D1023 | B25: 47987 | E25: Male | F25: Individual Donor | G25: N | I25: HOME | J25: Y | K25: 1 | L25: $0 | M25: $0 | N25: $1 | O25: $0 | P25: $0 | Q25: 1 | R25: Y
A26: D1024 | B26: 28472 | C26: 63 | D26: Married | E26: Male | F26: Community Partner | G26: Y | J26: Y | K26: 1 | L26: $0 | M26: $0 | N26: $0 | O26: $0 | P26: $0 | Q26: 0 | R26: N | S26: 1954-01-11
A27: D1025 | B27: 6411 | C27: 51 | E27: Male | F27: Community Partner | G27: N | J27: N | K27: 0 | L27: $0 | M27: $0 | N27: $0 | O27: $0 | P27: $0 | Q27: 169 | R27: Y | S27: 1966-08-21
A28: D1026 | B28: 41540 | C28: 30 | E28: Male | F28: Community Partner | G28: Y | I28: HOME | J28: Y | K28: 1 | L28: $0 | M28: $0 | N28: $0 | O28: $0 | P28: $0 | Q28: 100 | R28: Y | S28: 1987-05-13
A29: D1027 | B29: 36353 | E29: Male | F29: Individual Donor | G29: N | I29: HOME | J29: Y | K29: 1 | L29: $0 | M29: $410 | N29: $300 | O29: $0 | P29: $0 | Q29: 710 | R29: Y
A30: D1028 | B30: 42408 | E30: Female | F30: Individual Donor | G30: N | I30: HOME | J30: N | K30: 1 | L30: $0 | M30: $0 | N30: $0 | O30: $0 | P30: $0 | Q30: 325 | R30: Y
A31: D1029 | C31: 43 | E31: Male | F31: Community Partner | G31: Y | I31: HOME | J31: N | K31: 1 | L31: $0 | M31: $0 | N31: $0 | O31: $0 | P31: $0 | Q31: 0 | R31: N | S31: 1974-08-08
A32: D1030 | B32: 90265 | E32: Male | F32: Individual Donor | G32: N | I32: HOME | J32: N | K32: 1 | L32: $0 | M32: $0 | N32: $0 | O32: $0 | P32: $0 | Q32: 0 | R32: N
A33: D1031 | B33: 33811 | E33: Male | F33: Community Partner | G33: N | I33: HOME | J33: N | K33: 1 | L33: $0 | M33: $0 | N33: $0 | O33: $0 | P33: $122 | Q33: 122 | R33: Y
A34: D1032 | B34: 90265 | C34: 36 | E34: Female | F34: Individual Donor | G34: N | I34: HOME | J34: N | K34: 0 | L34: $0 | M34: $0 | N34: $0 | O34: $0 | P34: $0 | Q34: 1 | R34: Y | S34: 1981-09-13
A35: D1033 | B35: 9499 | E35: Female | F35: Individual Donor | G35: N | H35: $100,000-$249,999 | I35: HOME | J35: N | K35: 1 | L35: $0 | M35: $0 | N35: $0 | O35: $0 | P35: $0 | Q35: 8 | R35: Y
A36: D1034 | B36: 14127 | E36: Male | F36: Individual Donor | G36: N | I36: HOME | J36: N | K36: 2 | L36: $0 | M36: $0 | N36: $0 | O36: $0 | P36: $0 | Q36: 0 | R36: N
A37: D1035 | B37: 17509 | E37: Male | F37: Individual Donor | G37: N | I37: HOME | J37: N | K37: 1 | L37: $0 | M37: $0 | N37: $0 | O37: $1 | P37: $0 | Q37: 2529 | R37: Y
A38: D1036 | B38: 32655 | D38: Married | E38: Female | F38: Family Donor | G38: N | I38: HOME | J38: N | K38: 1 | L38: $0 | M38: $0 | N38: $0 | O38: $0 | P38: $0 | Q38: 250 | R38: Y
A39: D1037 | B39: 59845 | D39: Single | E39: Male | F39: Individual Donor | G39: N | I39: HOME | J39: Y | K39: 0 | L39: $0 | M39: $0 | N39: $0 | O39: $0 | P39: $0 | Q39: 0 | R39: N
A40: D1038 | B40: 68317 | C40: 46 | D40: Single | E40: Male | F40: Community Partner | G40: Y | I40: HOME | J40: Y | K40: 1 | L40: $0 | M40: $0 | N40: $0 | O40: $0 | P40: $0 | Q40: 25 | R40: Y | S40: 1971-05-22
...

Sheet Raw_Volunteers
A1: VolunteerID | B1: LinkedDonorID | C1: Volunteer Name | D1: Shift Date | E1: Role | F1: Location | G1: Hours
A2: V2001 | B2: D1259 | C2: Elizabeth Wright | D2: 03/03/2025 | E2: Warehouse Loading | F2: Main Warehouse | G2: 3
A3: V2001 | B3: D1259 | C3: Elizabeth Wright | D3: 05/24/2026 | E3: Food Sorting | F3: Main Warehouse | G3: 6
A4: V2001 | B4: D1259 | C4: Elizabeth Wright | D4: 12/29/2024 | E4: Warehouse Loading | F4: Downtown Pantry | G4: 2
A5: V2002 | B5: D1351-DUP | C5: Kevin Young | D5: 05/10/2025 | E5: Mobile Distribution Driver | F5: Mobile Unit - Route A | G5: 4
A6: V2002 | B6: D1351-DUP | C6: Kevin Young | D6: 07/13/2025 | E6: Event Setup | F6: Mobile Unit - Route B | G6: 3
A7: V2002 | B7: D1351-DUP | C7: Kevin Young | D7: 06/20/2025 | E7: Front Desk Greeter | F7: Downtown Pantry | G7: 2
A8: V2002 | B8: D1351-DUP | C8: Kevin Young | D8: 02/03/2024 | E8: Front Desk Greeter | F8: Mobile Unit - Route B | G8: 2
A9: V2002 | B9: D1351-DUP | C9: Kevin Young | D9: 08/30/2025 | E9: Warehouse Loading | F9: Mobile Unit - Route B | G9: 3
A10: V2002 | B10: D1351-DUP | C10: Kevin Young | D10: 05/12/2026 | E10: Event Setup | F10: Community Center Site | G10: 2
A11: V2002 | B11: D1351-DUP | C11: Kevin Young | D11: 02/04/2025 | E11: Pantry Stocking | F11: Mobile Unit - Route A | G11: 3
A12: V2002 | B12: D1351-DUP | C12: Kevin Young | D12: 01/15/2025 | E12: Front Desk Greeter | F12: Downtown Pantry | G12: 2
A13: V2003 | B13: D1605 | C13: Donald King | D13: 07/03/2024 | E13: Warehouse Loading | F13: Mobile Unit - Route A | G13: 3
... A59: V2009 | B59: D1118 | C59: Kenneth Perez | D59: 11/16/2024 | E59: Client Intake Assistant | F59: Mobile Unit - Route B | G59: 3
A60: V2009 | B60: D1118 | C60: Kenneth Perez | D60: 11/28/2024 | E60: Pantry Stocking | F60: Downtown Pantry
A61: V2009 | B61: D1118 | C61: Kenneth Perez | D61: 03/30/2024 | E61: Event Setup | F61: Mobile Unit - Route A | G61: 3
A62: V2009 | B62: D1118 | C62: Kenneth Perez | D62: 04/17/2024 | E62: Food Sorting | F62: Downtown Pantry | G62: 2
A63: V2009 | B63: D1118 | C63: Kenneth Perez | D63: 02/17/2025 | E63: Event Setup | F63: Main Warehouse | G63: 3
A64: V2009 | B64: D1118 | C64: Kenneth Perez | D64: 01/08/2026 | E64: Mobile Distribution Driver | F64: Mobile Unit - Route B | G64: 3
A65: V2009 | B65: D1118 | C65: Kenneth Perez | D65: 12/25/2024 | E65: Food Sorting | F65: Main Warehouse | G65: 3
A66: V2009 | B66: D1118 | C66: Kenneth Perez | D66: 05/27/2025 | E66: Mobile Distribution Driver | F66: Downtown Pantry | G66: 2
A67: V2009 | B67: D1118 | C67: Kenneth Perez | D67: 09/15/2024 | E67: Event Setup | F67: Mobile Unit - Route A | G67: 2
A68: V2009 | B68: D1118 | C68: Kenneth Perez | D68: 03/18/2024 | E68: Client Intake Assistant | F68: Downtown Pantry | G68: 2
A69: V2010 | B69: D1635 | C69: Charles Lee | D69: 12/14/2024 | E69: Front Desk Greeter | F69: Downtown Pantry | G69: 2
A70: V2010 | B70: D1635 | C70: Charles Lee | D70: 05/15/2026 | E70: Food Sorting | F70: Downtown Pantry | G70: 2
A71: V2010 | B71: D1635 | C71: Charles Lee | D71: 04/06/2026 | E71: Client Intake Assistant | F71: Mobile Unit - Route A | G71: 2
A72: V2010 | B72: D1635 | C72: Charles Lee | D72: 03/03/2025 | E72: pantry stocking | F72: Community Center Site | G72: 2
... A84: V2014 | B84: D1351 | C84: Donald Jones | D84: 10/13/2024 | E84: Mobile Distribution Driver | F84: Downtown Pantry | G84: 4
A85: V2014 | B85: D1351 | C85: Donald Jones | D85: 03/05/2026 | E85: Front Desk Greeter | F85: Downtown Pantry
A86: V2014 | B86: D1351 | C86: Donald Jones | D86: 10/23/2025 | E86: Client Intake Assistant | F86: Community Center Site | G86: 4
A87: V2014 | B87: D1351 | C87: Donald Jones | D87: 12/19/2024 | E87: Warehouse Loading | F87: Community Center Site
A88: V2014 | B88: D1351 | C88: Donald Jones | D88: 10/28/2024 | E88: Pantry Stocking | F88: Downtown Pantry | G88: 2
A89: V2014 | B89: D1351 | C89: Donald Jones | D89: 08/12/2025 | E89: Event Setup | F89: Main Warehouse | G89: 3
A90: V2014 | B90: D1351 | C90: Donald Jones | D90: 07/31/2025 | E90: Warehouse Loading | F90: Main Warehouse | G90: 5
A91: V2014 | B91: D1351 | C91: Donald Jones | D91: 12/12/2025 | E91: Client Intake Assistant | F91: Community Center Site | G91: 2
A92: V2014 | B92: D1351 | C92: Donald Jones | D92: 08/17/2024 | E92: Mobile Distribution Driver | F92: Downtown Pantry | G92: 2
A93: V2014 | B93: D1351 | C93: Donald Jones | D93: 04/29/2024 | E93: Warehouse Loading | F93: Mobile Unit - Route B | G93: 4
A94: V2014 | B94: D1351 | C94: Donald Jones | D94: 05/16/2024 | E94: Front Desk Greeter | F94: Main Warehouse | G94: 3
A95: V2014 | B95: D1351 | C95: Donald Jones | D95: 09/19/2025 | E95: Holiday Box Packing | F95: Main Warehouse | G95: 2
A96: V2015 | B96: D1237 | C96: Linda Wilson | D96: 01/03/2024 | E96: Holiday Box Packing | F96: Community Center Site | G96: 3
...

Sheet Raw_Outreach
A1: Staff Member | B1: Contact Method | C1: Date | D1: Donor/Volunteer Name | E1: Notes | F1: Substantive Contact | G1: Outcome
A2: Ann Marie Levier | B2: Email | C2: 12/1/17 | D2: Dominic Richards | E2: Sent Dominic an email asking for an update if he would like to move ahead with a gift to establish the full Graduate Student Honors Program based on how pleased he was with the intern program | F2: Y | G2: Positive
A3: Ann Marie Levier | B3: Email | C3: 12/1/17 | D3: William Bendrich | E3: Emailed Dr. Jonathan Winters, who have ties to Dr. Bendrich, regarding a gift to fund a Student Honors Program based on his verbal interest | F3: Y | G3: Positive
A4: Ann Marie Levier | B4: Letter | C4: 11/30/17 | D4: Belinda Carlyle | E4: Sent Belinda an upgrade brochure, appeal letter and envelope, as well as a handwritten note asking for her to become a leadership annual fund donor with a gift of $1,000 | F4: Y | G4: Positive
A5: Deborah Mettier | B5: Phone | C5: 11/29/17 | D5: Donna Gilbert | E5: $50k to extend Kendrick Memorial Undergraduate Scholarship and create Guiles Memorial Student Scholarship based on board meeting and verbal commtiment | F5: Y | G5: Positive
A6: Ann Marie Levier | B6: Letter | C6: 11/27/17 | D6: Jeffrey Jantz | E6: Sent upgrade brochure asking Jeffrey and Julie to become a leadership annual fund donor by making a gift of $1,000 or more, and said I'd be happy to send information about our Leadership Society | F6: Y | G6: Positive
A7: Ann Marie Levier | B7: Letter | C7: 11/24/17 | D7: Marsha Kenmore | E7: Sent Marsha an leadership annual fund upgrade brochure with a handwritten note asking her to become a leadership annual fund donor with a gift of $5,000 | F7: Y | G7: Positive
A8: Ann Marie Levier | B8: Letter | C8: 11/24/17 | D8: Kenneth Smith | E8: Sent upgrade brochure to Kenneth thanking them for their support since 2000 and asking them to become leadership annual fund donors with a gift of $2,500 | F8: Y | G8: Positive
A9: Bill Bamers | B9: Visit | C9: 11/20/17 | D9: Jennifer Ballens | E9: Roger, Julie and Amy met Jennifer for a cultivation lunch in Palo Alto. Jennifer shared that she and Jack would like to try to get to the Ambassadors Society level to support research lab. | F9: Y | G9: Positive
A10: Carlos Bendiga | B10: Email | C10: 10/30/17 | D10: Barbara Benaldi | E10: Not available during next trip to Seattle. Declined last meeting. Will try again in Winter. | F10: N | G10: Negative
A11: Ann Marie Levier | B11: Email | C11: 10/27/17 | D11: Jeff Zink | E11: Emailed about continued funding or guidance regarding facilities project based on lab meeting | F11: N | G11: Positive
A12: Ann Marie Levier | B12: Email | C12: 10/27/17 | D12: Laurie Stickel | E12: Laurie is not able to meet now (too busy) | F12: N | G12: Negative
... A197: April Catson | B197: Visit | C197: 8/27/17 | D197: Dori Keller | E197: Definitely interested in the University and would like a meeting next month. | F197: N | G197: Positive

Sheet Clean_Donors
A1: DonorID | B1: Duplicate Flag | C1: ZIP Code | D1: Age | E1: Marital Status | F1: Gender | G1: Donor Category (Clean) | H1: Volunteer Engaged | I1: Wealth Rating | J1: Preferred Contact Type (Clean) | K1: Email on File | L1: Consecutive Years Giving | M1: Giving FY2021 | N1: Giving FY2022 | O1: Giving FY2023 | P1: Giving FY2024 | Q1: Giving FY2025 | R1: Total Lifetime Giving | S1: Is Donor | T1: Birth Date | U1: Lapsed Donor Flag | V1: Giving Rank (helper) | W1: Lapsed Rank (helper)
A2: =Raw_Donors!A2 -> D1000 | B2: =IF(ISNUMBER(SEARCH("-DUP",A2)),"Duplicate ID","") | C2: =Raw_Donors!B2 -> 46743 | D2: =Raw_Donors!C2 -> 0 | E2: =IFERROR(IF(Raw_Donors!D2="","Unknown",Raw_Donors!D2),"Unknown") -> Unknown | F2: =IFERROR(IF(Raw_Donors!E2="","Unknown",Raw_Donors!E2),"Unknown") -> Female | G2: =PROPER(TRIM(Raw_Donors!F2)) -> Individual Donor | H2: =IFERROR(IF(Raw_Donors!G2="","N",Raw_Donors!G2),"N") -> N | I2: =IF(Raw_Donors!H2="","Not Rated",Raw_Donors!H2) -> Not Rated | J2: =IF(TRIM(Raw_Donors!I2)="","Unknown",TRIM(Raw_Donors!I2)) -> HOME | K2: =Raw_Donors!J2 -> N | L2: =Raw_Donors!K2 -> 1 | M2: =IFERROR(VALUE(SUBSTITUTE(SUBSTITUTE(Raw_Donors!L2,"$",""),",","")),0) -> 0 | N2: =IFERROR(VALUE(SUBSTITUTE(SUBSTITUTE(Raw_Donors!M2,"$",""),",","")),0) -> 0 | O2: =IFERROR(VALUE(SUBSTITUTE(SUBSTITUTE(Raw_Donors!N2,"$",""),",","")),0) -> 0 | P2: =IFERROR(VALUE(SUBSTITUTE(SUBSTITUTE(Raw_Donors!O2,"$",""),",","")),0) -> 0 | Q2: =IFERROR(VALUE(SUBSTITUTE(SUBSTITUTE(Raw_Donors!P2,"$",""),",","")),0) -> 0 | R2: =Raw_Donors!Q2 -> 0 | S2: =Raw_Donors!R2 -> N | T2: =IF(Raw_Donors!S2="","",Raw_Donors!S2) | U2: =IF(AND((O2+P2)>0,Q2=0),"Lapsed - Follow Up","") | V2: =RANK(R2,$R$2:$R$759)+COUNTIF($R$2:R2,R2)-1 -> 557 | W2: =IF(U2="Lapsed - Follow Up",COUNTIF($U$2:U2,"Lapsed - Follow Up"),"")
A3: =Raw_Donors!A3 -> D1001 | B3: =IF(ISNUMBER(SEARCH("-DUP",A3)),"Duplicate ID","") | C3: =Raw_Donors!B3 -> 27054 | D3: =Raw_Donors!C3 -> 0 | E3: =IFERROR(IF(Raw_Donors!D3="","Unknown",Raw_Donors!D3),"Unknown") -> Unknown | F3: =IFERROR(IF(Raw_Donors!E3="","Unknown",Raw_Donors!E3),"Unknown") -> Male | G3: =PROPER(TRIM(Raw_Donors!F3)) -> Family Donor | H3: =IFERROR(IF(Raw_Donors!G3="","N",Raw_Donors!G3),"N") -> N | I3: =IF(Raw_Donors!H3="","Not Rated",Raw_Donors!H3) -> Not Rated | J3: =IF(TRIM(Raw_Donors!I3)="","Unknown",TRIM(Raw_Donors!I3)) -> BUSN | K3: =Raw_Donors!J3 -> Y | L3: =Raw_Donors!K3 -> 0 | M3: =IFERROR(VALUE(SUBSTITUTE(SUBSTITUTE(Raw_Donors!L3,"$",""),",","")),0) -> 0 | N3: =IFERROR(VALUE(SUBSTITUTE(SUBSTITUTE(Raw_Donors!M3,"$",""),",","")),0) -> 0 | O3: =IFERROR(VALUE(SUBSTITUTE(SUBSTITUTE(Raw_Donors!N3,"$",""),",","")),0) -> 0 | P3: =IFERROR(VALUE(SUBSTITUTE(SUBSTITUTE(Raw_Donors!O3,"$",""),",","")),0) -> 0 | Q3: =IFERROR(VALUE(SUBSTITUTE(SUBSTITUTE(Raw_Donors!P3,"$",""),",","")),0) -> 0 | R3: =Raw_Donors!Q3 -> 334 | S3: =Raw_Donors!R3 -> Y | T3: =IF(Raw_Donors!S3="","",Raw_Donors!S3) | U3: =IF(AND((O3+P3)>0,Q3=0),"Lapsed - Follow Up","") | V3: =RANK(R3,$R$2:$R$759)+COUNTIF($R$2:R3,R3)-1 -> 130 | W3: =IF(U3="Lapsed - Follow Up",COUNTIF($U$2:U3,"Lapsed - Follow Up"),"")
A4: =Raw_Donors!A4 -> D1002 | B4: =IF(ISNUMBER(SEARCH("-DUP",A4)),"Duplicate ID","") | C4: =Raw_Donors!B4 -> 45843 | D4: =Raw_Donors!C4 -> 0 | E4: =IFERROR(IF(Raw_Donors!D4="","Unknown",Raw_Donors!D4),"Unknown") -> Unknown | F4: =IFERROR(IF(Raw_Donors!E4="","Unknown",Raw_Donors!E4),"Unknown") -> Male | G4: =PROPER(TRIM(Raw_Donors!F4)) -> Individual Donor | H4: =IFERROR(IF(Raw_Donors!G4="","N",Raw_Donors!G4),"N") -> N | I4: =IF(Raw_Donors!H4="","Not Rated",Raw_Donors!H4) -> Not Rated | J4: =IF(TRIM(Raw_Donors!I4)="","Unknown",TRIM(Raw_Donors!I4)) -> HOME | K4: =Raw_Donors!J4 -> N | L4: =Raw_Donors!K4 -> 1 | M4: =IFERROR(VALUE(SUBSTITUTE(SUBSTITUTE(Raw_Donors!L4,"$",""),",","")),0) -> 0 | N4: =IFERROR(VALUE(SUBSTITUTE(SUBSTITUTE(Raw_Donors!M4,"$",""),",","")),0) -> 0 | O4: =IFERROR(VALUE(SUBSTITUTE(SUBSTITUTE(Raw_Donors!N4,"$",""),",","")),0) -> 0 | P4: =IFERROR(VALUE(SUBSTITUTE(SUBSTITUTE(Raw_Donors!O4,"$",""),",","")),0) -> 0 | Q4: =IFERROR(VALUE(SUBSTITUTE(SUBSTITUTE(Raw_Donors!P4,"$",""),",","")),0) -> 0 | R4: =Raw_Donors!Q4 -> 870 | S4: =Raw_Donors!R4 -> Y | T4: =IF(Raw_Donors!S4="","",Raw_Donors!S4) | U4: =IF(AND((O4+P4)>0,Q4=0),"Lapsed - Follow Up","") | V4: =RANK(R4,$R$2:$R$759)+COUNTIF($R$2:R4,R4)-1 -> 63 | W4: =IF(U4="Lapsed - Follow Up",COUNTIF($U$2:U4,"Lapsed - Follow Up"),"")
A5: =Raw_Donors!A5 -> D1003 | B5: =IF(ISNUMBER(SEARCH("-DUP",A5)),"Duplicate ID","") | C5: =Raw_Donors!B5 -> 33953 | D5: =Raw_Donors!C5 -> 0 | E5: =IFERROR(IF(Raw_Donors!D5="","Unknown",Raw_Donors!D5),"Unknown") -> Unknown | F5: =IFERROR(IF(Raw_Donors!E5="","Unknown",Raw_Donors!E5),"Unknown") -> Uknown | G5: =PROPER(TRIM(Raw_Donors!F5)) -> Individual Donor | H5: =IFERROR(IF(Raw_Donors!G5="","N",Raw_Donors!G5),"N") -> N | I5: =IF(Raw_Donors!H5="","Not Rated",Raw_Donors!H5) -> Not Rated | J5: =IF(TRIM(Raw_Donors!I5)="","Unknown",TRIM(Raw_Donors!I5)) -> HOME | K5: =Raw_Donors!J5 -> N | L5: =Raw_Donors!K5 -> 0 | M5: =IFERROR(VALUE(SUBSTITUTE(SUBSTITUTE(Raw_Donors!L5,"$",""),",","")),0) -> 0 | N5: =IFERROR(VALUE(SUBSTITUTE(SUBSTITUTE(Raw_Donors!M5,"$",""),",","")),0) -> 0 | O5: =IFERROR(VALUE(SUBSTITUTE(SUBSTITUTE(Raw_Donors!N5,"$",""),",","")),0) -> 0 | P5: =IFERROR(VALUE(SUBSTITUTE(SUBSTITUTE(Raw_Donors!O5,"$",""),",","")),0) -> 0 | Q5: =IFERROR(VALUE(SUBSTITUTE(SUBSTITUTE(Raw_Donors!P5,"$",""),",","")),0) -> 0 | R5: =Raw_Donors!Q5 -> 0 | S5: =Raw_Donors!R5 -> N | T5: =IF(Raw_Donors!S5="","",Raw_Donors!S5) | U5: =IF(AND((O5+P5)>0,Q5=0),"Lapsed - Follow Up","") | V5: =RANK(R5,$R$2:$R$759)+COUNTIF($R$2:R5,R5)-1 -> 558 | W5: =IF(U5="Lapsed - Follow Up",COUNTIF($U$2:U5,"Lapsed - Follow Up"),"")
A6: =Raw_Donors!A6 -> D1004 | B6: =IF(ISNUMBER(SEARCH("-DUP",A6)),"Duplicate ID","") | C6: =Raw_Donors!B6 -> 63013 | D6: =Raw_Donors!C6 -> 39 | E6: =IFERROR(IF(Raw_Donors!D6="","Unknown",Raw_Donors!D6),"Unknown") -> Unknown | F6: =IFERROR(IF(Raw_Donors!E6="","Unknown",Raw_Donors!E6),"Unknown") -> Female | G6: =PROPER(TRIM(Raw_Donors!F6)) -> Individual Donor | H6: =IFERROR(IF(Raw_Donors!G6="","N",Raw_Donors!G6),"N") -> N | I6: =IF(Raw_Donors!H6="","Not Rated",Raw_Donors!H6) -> Not Rated | J6: =IF(TRIM(Raw_Donors!I6)="","Unknown",TRIM(Raw_Donors!I6)) -> HOME | K6: =Raw_Donors!J6 -> N | L6: =Raw_Donors!K6 -> 0 | M6: =IFERROR(VALUE(SUBSTITUTE(SUBSTITUTE(Raw_Donors!L6,"$",""),",","")),0) -> 0 | N6: =IFERROR(VALUE(SUBSTITUTE(SUBSTITUTE(Raw_Donors!M6,"$",""),",","")),0) -> 0 | O6: =IFERROR(VALUE(SUBSTITUTE(SUBSTITUTE(Raw_Donors!N6,"$",""),",","")),0) -> 0 | P6: =IFERROR(VALUE(SUBSTITUTE(SUBSTITUTE(Raw_Donors!O6,"$",""),",","")),0) -> 0 | Q6: =IFERROR(VALUE(SUBSTITUTE(SUBSTITUTE(Raw_Donors!P6,"$",""),",","")),0) -> 0 | R6: =Raw_Donors!Q6 -> 490 | S6: =Raw_Donors!R6 -> Y | T6: =IF(Raw_Donors!S6="","",Raw_Donors!S6) -> 1978-05-22 | U6: =IF(AND((O6+P6)>0,Q6=0),"Lapsed - Follow Up","") | V6: =RANK(R6,$R$2:$R$759)+COUNTIF($R$2:R6,R6)-1 -> 98 | W6: =IF(U6="Lapsed - Follow Up",COUNTIF($U$2:U6,"Lapsed - Follow Up"),"")
A7: =Raw_Donors!A7 -> D1005 | B7: =IF(ISNUMBER(SEARCH("-DUP",A7)),"Duplicate ID","") | C7: =Raw_Donors!B7 -> 41832 | D7: =Raw_Donors!C7 -> 55 | E7: =IFERROR(IF(Raw_Donors!D7="","Unknown",Raw_Donors!D7),"Unknown") -> Unknown | F7: =IFERROR(IF(Raw_Donors!E7="","Unknown",Raw_Donors!E7),"Unknown") -> Male | G7: =PROPER(TRIM(Raw_Donors!F7)) -> Community Partner | H7: =IFERROR(IF(Raw_Donors!G7="","N",Raw_Donors!G7),"N") -> N | I7: =IF(Raw_Donors!H7="","Not Rated",Raw_Donors!H7) -> Not Rated | J7: =IF(TRIM(Raw_Donors!I7)="","Unknown",TRIM(Raw_Donors!I7)) -> HOME | K7: =Raw_Donors!J7 -> N | L7: =Raw_Donors!K7 -> 1 | M7: =IFERROR(VALUE(SUBSTITUTE(SUBSTITUTE(Raw_Donors!L7,"$",""),",","")),0) -> 0 | N7: =IFERROR(VALUE(SUBSTITUTE(SUBSTITUTE(Raw_Donors!M7,"$",""),",","")),0) -> 0 | O7: =IFERROR(VALUE(SUBSTITUTE(SUBSTITUTE(Raw_Donors!N7,"$",""),",","")),0) -> 0 | P7: =IFERROR(VALUE(SUBSTITUTE(SUBSTITUTE(Raw_Donors!O7,"$",""),",","")),0) -> 0 | Q7: =IFERROR(VALUE(SUBSTITUTE(SUBSTITUTE(Raw_Donors!P7,"$",""),",","")),0) -> 0 | R7: =Raw_Donors!Q7 -> 0 | S7: =Raw_Donors!R7 -> N | T7: =IF(Raw_Donors!S7="","",Raw_Donors!S7) -> 1962-01-21 | U7: =IF(AND((O7+P7)>0,Q7=0),"Lapsed - Follow Up","") | V7: =RANK(R7,$R$2:$R$759)+COUNTIF($R$2:R7,R7)-1 -> 559 | W7: =IF(U7="Lapsed - Follow Up",COUNTIF($U$2:U7,"Lapsed - Follow Up"),"")
A8: =Raw_Donors!A8 -> D1006 | B8: =IF(ISNUMBER(SEARCH("-DUP",A8)),"Duplicate ID","") | C8: =Raw_Donors!B8 -> 35402 | D8: =Raw_Donors!C8 -> 0 | E8: =IFERROR(IF(Raw_Donors!D8="","Unknown",Raw_Donors!D8),"Unknown") -> Unknown | F8: =IFERROR(IF(Raw_Donors!E8="","Unknown",Raw_Donors!E8),"Unknown") -> Male | G8: =PROPER(TRIM(Raw_Donors!F8)) -> Individual Donor | H8: =IFERROR(IF(Raw_Donors!G8="","N",Raw_Donors!G8),"N") -> Y | I8: =IF(Raw_Donors!H8="","Not Rated",Raw_Donors!H8) -> Not Rated | J8: =IF(TRIM(Raw_Donors!I8)="","Unknown",TRIM(Raw_Donors!I8)) -> HOME | K8: =Raw_Donors!J8 -> N | L8: =Raw_Donors!K8 -> 0 | M8: =IFERROR(VALUE(SUBSTITUTE(SUBSTITUTE(Raw_Donors!L8,"$",""),",","")),0) -> 0 | N8: =IFERROR(VALUE(SUBSTITUTE(SUBSTITUTE(Raw_Donors!M8,"$",""),",","")),0) -> 0 | O8: =IFERROR(VALUE(SUBSTITUTE(SUBSTITUTE(Raw_Donors!N8,"$",""),",","")),0) -> 0 | P8: =IFERROR(VALUE(SUBSTITUTE(SUBSTITUTE(Raw_Donors!O8,"$",""),",","")),0) -> 0 | Q8: =IFERROR(VALUE(SUBSTITUTE(SUBSTITUTE(Raw_Donors!P8,"$",""),",","")),0) -> 1 | R8: =Raw_Donors!Q8 -> 50 | S8: =Raw_Donors!R8 -> Y | T8: =IF(Raw_Donors!S8="","",Raw_Donors!S8) | U8: =IF(AND((O8+P8)>0,Q8=0),"Lapsed - Follow Up","") | V8: =RANK(R8,$R$2:$R$759)+COUNTIF($R$2:R8,R8)-1 -> 364 | W8: =IF(U8="Lapsed - Follow Up",COUNTIF($U$2:U8,"Lapsed - Follow Up"),"")
A9: =Raw_Donors!A9 -> D1007 | B9: =IF(ISNUMBER(SEARCH("-DUP",A9)),"Duplicate ID","") | C9: =Raw_Donors!B9 -> 25714 | D9: =Raw_Donors!C9 -> 23 | E9: =IFERROR(IF(Raw_Donors!D9="","Unknown",Raw_Donors!D9),"Unknown") -> Unknown | F9: =IFERROR(IF(Raw_Donors!E9="","Unknown",Raw_Donors!E9),"Unknown") -> Female | G9: =PROPER(TRIM(Raw_Donors!F9)) -> Individual Donor | H9: =IFERROR(IF(Raw_Donors!G9="","N",Raw_Donors!G9),"N") -> N | I9: =IF(Raw_Donors!H9="","Not Rated",Raw_Donors!H9) -> Not Rated | J9: =IF(TRIM(Raw_Donors!I9)="","Unknown",TRIM(Raw_Donors!I9)) -> HOME | K9: =Raw_Donors!J9 -> N | L9: =Raw_Donors!K9 -> 0 | M9: =IFERROR(VALUE(SUBSTITUTE(SUBSTITUTE(Raw_Donors!L9,"$",""),",","")),0) -> 0 | N9: =IFERROR(VALUE(SUBSTITUTE(SUBSTITUTE(Raw_Donors!M9,"$",""),",","")),0) -> 0 | O9: =IFERROR(VALUE(SUBSTITUTE(SUBSTITUTE(Raw_Donors!N9,"$",""),",","")),0) -> 0 | P9: =IFERROR(VALUE(SUBSTITUTE(SUBSTITUTE(Raw_Donors!O9,"$",""),",","")),0) -> 0 | Q9: =IFERROR(VALUE(SUBSTITUTE(SUBSTITUTE(Raw_Donors!P9,"$",""),",","")),0) -> 0 | R9: =Raw_Donors!Q9 -> 1000 | S9: =Raw_Donors!R9 -> Y | T9: =IF(Raw_Donors!S9="","",Raw_Donors!S9) -> 1994-05-13 | U9: =IF(AND((O9+P9)>0,Q9=0),"Lapsed - Follow Up","") | V9: =RANK(R9,$R$2:$R$759)+COUNTIF($R$2:R9,R9)-1 -> 58 | W9: =IF(U9="Lapsed - Follow Up",COUNTIF($U$2:U9,"Lapsed - Follow Up"),"")
A10: =Raw_Donors!A10 -> D1008 | B10: =IF(ISNUMBER(SEARCH("-DUP",A10)),"Duplicate ID","") | C10: =Raw_Donors!B10 -> 71635 | D10: =Raw_Donors!C10 -> 0 | E10: =IFERROR(IF(Raw_Donors!D10="","Unknown",Raw_Donors!D10),"Unknown") -> Unknown | F10: =IFERROR(IF(Raw_Donors!E10="","Unknown",Raw_Donors!E10),"Unknown") -> Male | G10: =PROPER(TRIM(Raw_Donors!F10)) -> Individual Donor | H10: =IFERROR(IF(Raw_Donors!G10="","N",Raw_Donors!G10),"N") -> N | I10: =IF(Raw_Donors!H10="","Not Rated",Raw_Donors!H10) -> Not Rated | J10: =IF(TRIM(Raw_Donors!I10)="","Unknown",TRIM(Raw_Donors!I10)) -> HOME | K10: =Raw_Donors!J10 -> N | L10: =Raw_Donors!K10 -> 1 | M10: =IFERROR(VALUE(SUBSTITUTE(SUBSTITUTE(Raw_Donors!L10,"$",""),",","")),0) -> 0 | N10: =IFERROR(VALUE(SUBSTITUTE(SUBSTITUTE(Raw_Donors!M10,"$",""),",","")),0) -> 0 | O10: =IFERROR(VALUE(SUBSTITUTE(SUBSTITUTE(Raw_Donors!N10,"$",""),",","")),0) -> 0 | P10: =IFERROR(VALUE(SUBSTITUTE(SUBSTITUTE(Raw_Donors!O10,"$",""),",","")),0) -> 0 | Q10: =IFERROR(VALUE(SUBSTITUTE(SUBSTITUTE(Raw_Donors!P10,"$",""),",","")),0) -> 0 | R10: =Raw_Donors!Q10 -> 0 | S10: =Raw_Donors!R10 -> N | T10: =IF(Raw_Donors!S10="","",Raw_Donors!S10) | U10: =IF(AND((O10+P10)>0,Q10=0),"Lapsed - Follow Up","") | V10: =RANK(R10,$R$2:$R$759)+COUNTIF($R$2:R10,R10)-1 -> 560 | W10: =IF(U10="Lapsed - Follow Up",COUNTIF($U$2:U10,"Lapsed - Follow Up"),"")
A11: =Raw_Donors!A11 -> D1009 | B11: =IF(ISNUMBER(SEARCH("-DUP",A11)),"Duplicate ID","") | C11: =Raw_Donors!B11 -> 29062 | D11: =Raw_Donors!C11 -> 0 | E11: =IFERROR(IF(Raw_Donors!D11="","Unknown",Raw_Donors!D11),"Unknown") -> Married | F11: =IFERROR(IF(Raw_Donors!E11="","Unknown",Raw_Donors!E11),"Unknown") -> Male | G11: =PROPER(TRIM(Raw_Donors!F11)) -> Individual Donor | H11: =IFERROR(IF(Raw_Donors!G11="","N",Raw_Donors!G11),"N") -> N | I11: =IF(Raw_Donors!H11="","Not Rated",Raw_Donors!H11) -> Not Rated | J11: =IF(TRIM(Raw_Donors!I11)="","Unknown",TRIM(Raw_Donors!I11)) -> HOME | K11: =Raw_Donors!J11 -> Y | L11: =Raw_Donors!K11 -> 1 | M11: =IFERROR(VALUE(SUBSTITUTE(SUBSTITUTE(Raw_Donors!L11,"$",""),",","")),0) -> 0 | N11: =IFERROR(VALUE(SUBSTITUTE(SUBSTITUTE(Raw_Donors!M11,"$",""),",","")),0) -> 0 | O11: =IFERROR(VALUE(SUBSTITUTE(SUBSTITUTE(Raw_Donors!N11,"$",""),",","")),0) -> 0 | P11: =IFERROR(VALUE(SUBSTITUTE(SUBSTITUTE(Raw_Donors!O11,"$",""),",","")),0) -> 0 | Q11: =IFERROR(VALUE(SUBSTITUTE(SUBSTITUTE(Raw_Donors!P11,"$",""),",","")),0) -> 100 | R11: =Raw_Donors!Q11 -> 100 | S11: =Raw_Donors!R11 -> Y | T11: =IF(Raw_Donors!S11="","",Raw_Donors!S11) | U11: =IF(AND((O11+P11)>0,Q11=0),"Lapsed - Follow Up","") | V11: =RANK(R11,$R$2:$R$759)+COUNTIF($R$2:R11,R11)-1 -> 271 | W11: =IF(U11="Lapsed - Follow Up",COUNTIF($U$2:U11,"Lapsed - Follow Up"),"")
A12: =Raw_Donors!A12 -> D1010 | B12: =IF(ISNUMBER(SEARCH("-DUP",A12)),"Duplicate ID","") | C12: =Raw_Donors!B12 -> 40224 | D12: =Raw_Donors!C12 -> 0 | E12: =IFERROR(IF(Raw_Donors!D12="","Unknown",Raw_Donors!D12),"Unknown") -> Unknown | F12: =IFERROR(IF(Raw_Donors!E12="","Unknown",Raw_Donors!E12),"Unknown") -> Male | G12: =PROPER(TRIM(Raw_Donors!F12)) -> Individual Donor | H12: =IFERROR(IF(Raw_Donors!G12="","N",Raw_Donors!G12),"N") -> N | I12: =IF(Raw_Donors!H12="","Not Rated",Raw_Donors!H12) -> Not Rated | J12: =IF(TRIM(Raw_Donors!I12)="","Unknown",TRIM(Raw_Donors!I12)) -> HOME | K12: =Raw_Donors!J12 -> N | L12: =Raw_Donors!K12 -> 1 | M12: =IFERROR(VALUE(SUBSTITUTE(SUBSTITUTE(Raw_Donors!L12,"$",""),",","")),0) -> 0 | N12: =IFERROR(VALUE(SUBSTITUTE(SUBSTITUTE(Raw_Donors!M12,"$",""),",","")),0) -> 0 | O12: =IFERROR(VALUE(SUBSTITUTE(SUBSTITUTE(Raw_Donors!N12,"$",""),",","")),0) -> 0 | P12: =IFERROR(VALUE(SUBSTITUTE(SUBSTITUTE(Raw_Donors!O12,"$",""),",","")),0) -> 0 | Q12: =IFERROR(VALUE(SUBSTITUTE(SUBSTITUTE(Raw_Donors!P12,"$",""),",","")),0) -> 0 | R12: =Raw_Donors!Q12 -> 0 | S12: =Raw_Donors!R12 -> N | T12: =IF(Raw_Donors!S12="","",Raw_Donors!S12) | U12: =IF(AND((O12+P12)>0,Q12=0),"Lapsed - Follow Up","") | V12: =RANK(R12,$R$2:$R$759)+COUNTIF($R$2:R12,R12)-1 -> 561 | W12: =IF(U12="Lapsed - Follow Up",COUNTIF($U$2:U12,"Lapsed - Follow Up"),"")
A13: =Raw_Donors!A13 -> D1011 | B13: =IF(ISNUMBER(SEARCH("-DUP",A13)),"Duplicate ID","") | C13: =Raw_Donors!B13 -> 5481 | D13: =Raw_Donors!C13 -> 0 | E13: =IFERROR(IF(Raw_Donors!D13="","Unknown",Raw_Donors!D13),"Unknown") -> Unknown | F13: =IFERROR(IF(Raw_Donors!E13="","Unknown",Raw_Donors!E13),"Unknown") -> Male | G13: =PROPER(TRIM(Raw_Donors!F13)) -> Community Partner | H13: =IFERROR(IF(Raw_Donors!G13="","N",Raw_Donors!G13),"N") -> Y | I13: =IF(Raw_Donors!H13="","Not Rated",Raw_Donors!H13) -> Not Rated | J13: =IF(TRIM(Raw_Donors!I13)="","Unknown",TRIM(Raw_Donors!I13)) -> HOME | K13: =Raw_Donors!J13 -> Y | L13: =Raw_Donors!K13 -> 3 | M13: =IFERROR(VALUE(SUBSTITUTE(SUBSTITUTE(Raw_Donors!L13,"$",""),",","")),0) -> 0 | N13: =IFERROR(VALUE(SUBSTITUTE(SUBSTITUTE(Raw_Donors!M13,"$",""),",","")),0) -> 0 | O13: =IFERROR(VALUE(SUBSTITUTE(SUBSTITUTE(Raw_Donors!N13,"$",""),",","")),0) -> 0 | P13: =IFERROR(VALUE(SUBSTITUTE(SUBSTITUTE(Raw_Donors!O13,"$",""),",","")),0) -> 0 | Q13: =IFERROR(VALUE(SUBSTITUTE(SUBSTITUTE(Raw_Donors!P13,"$",""),",","")),0) -> 0 | R13: =Raw_Donors!Q13 -> 0 | S13: =Raw_Donors!R13 -> N | T13: =IF(Raw_Donors!S13="","",Raw_Donors!S13) | U13: =IF(AND((O13+P13)>0,Q13=0),"Lapsed - Follow Up","") | V13: =RANK(R13,$R$2:$R$759)+COUNTIF($R$2:R13,R13)-1 -> 562 | W13: =IF(U13="Lapsed - Follow Up",COUNTIF($U$2:U13,"Lapsed - Follow Up"),"")
... A759: =Raw_Donors!A759 -> D1351-DUP | B759: =IF(ISNUMBER(SEARCH("-DUP",A759)),"Duplicate ID","") -> Duplicate ID | C759: =Raw_Donors!B759 -> 90265 | D759: =Raw_Donors!C759 -> 50 | E759: =IFERROR(IF(Raw_Donors!D759="","Unknown",Raw_Donors!D759),"Unknown") -> Unknown | F759: =IFERROR(IF(Raw_Donors!E759="","Unknown",Raw_Donors!E759),"Unknown") -> Female | G759: =PROPER(TRIM(Raw_Donors!F759)) -> Community Partner | H759: =IFERROR(IF(Raw_Donors!G759="","N",Raw_Donors!G759),"N") -> Y | I759: =IF(Raw_Donors!H759="","Not Rated",Raw_Donors!H759) -> Not Rated | J759: =IF(TRIM(Raw_Donors!I759)="","Unknown",TRIM(Raw_Donors!I759)) -> HOME | K759: =Raw_Donors!J759 -> N | L759: =Raw_Donors!K759 -> 1 | M759: =IFERROR(VALUE(SUBSTITUTE(SUBSTITUTE(Raw_Donors!L759,"$",""),",","")),0) -> 0 | N759: =IFERROR(VALUE(SUBSTITUTE(SUBSTITUTE(Raw_Donors!M759,"$",""),",","")),0) -> 0 | O759: =IFERROR(VALUE(SUBSTITUTE(SUBSTITUTE(Raw_Donors!N759,"$",""),",","")),0) -> 0 | P759: =IFERROR(VALUE(SUBSTITUTE(SUBSTITUTE(Raw_Donors!O759,"$",""),",","")),0) -> 0 | Q759: =IFERROR(VALUE(SUBSTITUTE(SUBSTITUTE(Raw_Donors!P759,"$",""),",","")),0) -> 0 | R759: =Raw_Donors!Q759 -> 240 | S759: =Raw_Donors!R759 -> Y | T759: =IF(Raw_Donors!S759="","",Raw_Donors!S759) -> 1967-05-08 | U759: =IF(AND((O759+P759)>0,Q759=0),"Lapsed - Follow Up","") | V759: =RANK(R759,$R$2:$R$759)+COUNTIF($R$2:R759,R759)-1 -> 180 | W759: =IF(U759="Lapsed - Follow Up",COUNTIF($U$2:U759,"Lapsed - Follow Up"),"")

Sheet Clean_Volunteers
A1: VolunteerID | B1: Duplicate Flag | C1: Linked DonorID | D1: Also a Donor? | E1: Volunteer Name | F1: Shift Date | G1: Role (Clean) | H1: Location | I1: Hours (Clean)
A2: =Raw_Volunteers!A2 -> V2001 | B2: =IF(COUNTIFS(Raw_Volunteers!$A$2:$A$926,Raw_Volunteers!A2,Raw_Volunteers!$D$2:$D$926,Raw_Volunteers!D2,Raw_Volunteers!$E$2:$E$926,Raw_Volunteers!E2,Raw_Volunteers!$G$2:$G$926,Raw_Volunteers!G2)>1,"Possible Duplicate","") | C2: =Raw_Volunteers!B2 -> D1259 | D2: =IF(C2="","No","Yes") -> Yes | E2: =Raw_Volunteers!C2 -> Elizabeth Wright | F2: =Raw_Volunteers!D2 -> 03/03/2025 | G2: =PROPER(TRIM(Raw_Volunteers!E2)) -> Warehouse Loading | H2: =Raw_Volunteers!F2 -> Main Warehouse | I2: =IF(Raw_Volunteers!G2="",ROUND(AVERAGE(Raw_Volunteers!$G$2:$G$926),1),Raw_Volunteers!G2) -> 3
A3: =Raw_Volunteers!A3 -> V2001 | B3: =IF(COUNTIFS(Raw_Volunteers!$A$2:$A$926,Raw_Volunteers!A3,Raw_Volunteers!$D$2:$D$926,Raw_Volunteers!D3,Raw_Volunteers!$E$2:$E$926,Raw_Volunteers!E3,Raw_Volunteers!$G$2:$G$926,Raw_Volunteers!G3)>1,"Possible Duplicate","") | C3: =Raw_Volunteers!B3 -> D1259 | D3: =IF(C3="","No","Yes") -> Yes | E3: =Raw_Volunteers!C3 -> Elizabeth Wright | F3: =Raw_Volunteers!D3 -> 05/24/2026 | G3: =PROPER(TRIM(Raw_Volunteers!E3)) -> Food Sorting | H3: =Raw_Volunteers!F3 -> Main Warehouse | I3: =IF(Raw_Volunteers!G3="",ROUND(AVERAGE(Raw_Volunteers!$G$2:$G$926),1),Raw_Volunteers!G3) -> 6
A4: =Raw_Volunteers!A4 -> V2001 | B4: =IF(COUNTIFS(Raw_Volunteers!$A$2:$A$926,Raw_Volunteers!A4,Raw_Volunteers!$D$2:$D$926,Raw_Volunteers!D4,Raw_Volunteers!$E$2:$E$926,Raw_Volunteers!E4,Raw_Volunteers!$G$2:$G$926,Raw_Volunteers!G4)>1,"Possible Duplicate","") | C4: =Raw_Volunteers!B4 -> D1259 | D4: =IF(C4="","No","Yes") -> Yes | E4: =Raw_Volunteers!C4 -> Elizabeth Wright | F4: =Raw_Volunteers!D4 -> 12/29/2024 | G4: =PROPER(TRIM(Raw_Volunteers!E4)) -> Warehouse Loading | H4: =Raw_Volunteers!F4 -> Downtown Pantry | I4: =IF(Raw_Volunteers!G4="",ROUND(AVERAGE(Raw_Volunteers!$G$2:$G$926),1),Raw_Volunteers!G4) -> 2
A5: =Raw_Volunteers!A5 -> V2002 | B5: =IF(COUNTIFS(Raw_Volunteers!$A$2:$A$926,Raw_Volunteers!A5,Raw_Volunteers!$D$2:$D$926,Raw_Volunteers!D5,Raw_Volunteers!$E$2:$E$926,Raw_Volunteers!E5,Raw_Volunteers!$G$2:$G$926,Raw_Volunteers!G5)>1,"Possible Duplicate","") | C5: =Raw_Volunteers!B5 -> D1351-DUP | D5: =IF(C5="","No","Yes") -> Yes | E5: =Raw_Volunteers!C5 -> Kevin Young | F5: =Raw_Volunteers!D5 -> 05/10/2025 | G5: =PROPER(TRIM(Raw_Volunteers!E5)) -> Mobile Distribution Driver | H5: =Raw_Volunteers!F5 -> Mobile Unit - Route A | I5: =IF(Raw_Volunteers!G5="",ROUND(AVERAGE(Raw_Volunteers!$G$2:$G$926),1),Raw_Volunteers!G5) -> 4
A6: =Raw_Volunteers!A6 -> V2002 | B6: =IF(COUNTIFS(Raw_Volunteers!$A$2:$A$926,Raw_Volunteers!A6,Raw_Volunteers!$D$2:$D$926,Raw_Volunteers!D6,Raw_Volunteers!$E$2:$E$926,Raw_Volunteers!E6,Raw_Volunteers!$G$2:$G$926,Raw_Volunteers!G6)>1,"Possible Duplicate","") | C6: =Raw_Volunteers!B6 -> D1351-DUP | D6: =IF(C6="","No","Yes") -> Yes | E6: =Raw_Volunteers!C6 -> Kevin Young | F6: =Raw_Volunteers!D6 -> 07/13/2025 | G6: =PROPER(TRIM(Raw_Volunteers!E6)) -> Event Setup | H6: =Raw_Volunteers!F6 -> Mobile Unit - Route B | I6: =IF(Raw_Volunteers!G6="",ROUND(AVERAGE(Raw_Volunteers!$G$2:$G$926),1),Raw_Volunteers!G6) -> 3
A7: =Raw_Volunteers!A7 -> V2002 | B7: =IF(COUNTIFS(Raw_Volunteers!$A$2:$A$926,Raw_Volunteers!A7,Raw_Volunteers!$D$2:$D$926,Raw_Volunteers!D7,Raw_Volunteers!$E$2:$E$926,Raw_Volunteers!E7,Raw_Volunteers!$G$2:$G$926,Raw_Volunteers!G7)>1,"Possible Duplicate","") | C7: =Raw_Volunteers!B7 -> D1351-DUP | D7: =IF(C7="","No","Yes") -> Yes | E7: =Raw_Volunteers!C7 -> Kevin Young | F7: =Raw_Volunteers!D7 -> 06/20/2025 | G7: =PROPER(TRIM(Raw_Volunteers!E7)) -> Front Desk Greeter | H7: =Raw_Volunteers!F7 -> Downtown Pantry | I7: =IF(Raw_Volunteers!G7="",ROUND(AVERAGE(Raw_Volunteers!$G$2:$G$926),1),Raw_Volunteers!G7) -> 2
A8: =Raw_Volunteers!A8 -> V2002 | B8: =IF(COUNTIFS(Raw_Volunteers!$A$2:$A$926,Raw_Volunteers!A8,Raw_Volunteers!$D$2:$D$926,Raw_Volunteers!D8,Raw_Volunteers!$E$2:$E$926,Raw_Volunteers!E8,Raw_Volunteers!$G$2:$G$926,Raw_Volunteers!G8)>1,"Possible Duplicate","") | C8: =Raw_Volunteers!B8 -> D1351-DUP | D8: =IF(C8="","No","Yes") -> Yes | E8: =Raw_Volunteers!C8 -> Kevin Young | F8: =Raw_Volunteers!D8 -> 02/03/2024 | G8: =PROPER(TRIM(Raw_Volunteers!E8)) -> Front Desk Greeter | H8: =Raw_Volunteers!F8 -> Mobile Unit - Route B | I8: =IF(Raw_Volunteers!G8="",ROUND(AVERAGE(Raw_Volunteers!$G$2:$G$926),1),Raw_Volunteers!G8) -> 2
A9: =Raw_Volunteers!A9 -> V2002 | B9: =IF(COUNTIFS(Raw_Volunteers!$A$2:$A$926,Raw_Volunteers!A9,Raw_Volunteers!$D$2:$D$926,Raw_Volunteers!D9,Raw_Volunteers!$E$2:$E$926,Raw_Volunteers!E9,Raw_Volunteers!$G$2:$G$926,Raw_Volunteers!G9)>1,"Possible Duplicate","") | C9: =Raw_Volunteers!B9 -> D1351-DUP | D9: =IF(C9="","No","Yes") -> Yes | E9: =Raw_Volunteers!C9 -> Kevin Young | F9: =Raw_Volunteers!D9 -> 08/30/2025 | G9: =PROPER(TRIM(Raw_Volunteers!E9)) -> Warehouse Loading | H9: =Raw_Volunteers!F9 -> Mobile Unit - Route B | I9: =IF(Raw_Volunteers!G9="",ROUND(AVERAGE(Raw_Volunteers!$G$2:$G$926),1),Raw_Volunteers!G9) -> 3
A10: =Raw_Volunteers!A10 -> V2002 | B10: =IF(COUNTIFS(Raw_Volunteers!$A$2:$A$926,Raw_Volunteers!A10,Raw_Volunteers!$D$2:$D$926,Raw_Volunteers!D10,Raw_Volunteers!$E$2:$E$926,Raw_Volunteers!E10,Raw_Volunteers!$G$2:$G$926,Raw_Volunteers!G10)>1,"Possible Duplicate","") | C10: =Raw_Volunteers!B10 -> D1351-DUP | D10: =IF(C10="","No","Yes") -> Yes | E10: =Raw_Volunteers!C10 -> Kevin Young | F10: =Raw_Volunteers!D10 -> 05/12/2026 | G10: =PROPER(TRIM(Raw_Volunteers!E10)) -> Event Setup | H10: =Raw_Volunteers!F10 -> Community Center Site | I10: =IF(Raw_Volunteers!G10="",ROUND(AVERAGE(Raw_Volunteers!$G$2:$G$926),1),Raw_Volunteers!G10) -> 2
A11: =Raw_Volunteers!A11 -> V2002 | B11: =IF(COUNTIFS(Raw_Volunteers!$A$2:$A$926,Raw_Volunteers!A11,Raw_Volunteers!$D$2:$D$926,Raw_Volunteers!D11,Raw_Volunteers!$E$2:$E$926,Raw_Volunteers!E11,Raw_Volunteers!$G$2:$G$926,Raw_Volunteers!G11)>1,"Possible Duplicate","") | C11: =Raw_Volunteers!B11 -> D1351-DUP | D11: =IF(C11="","No","Yes") -> Yes | E11: =Raw_Volunteers!C11 -> Kevin Young | F11: =Raw_Volunteers!D11 -> 02/04/2025 | G11: =PROPER(TRIM(Raw_Volunteers!E11)) -> Pantry Stocking | H11: =Raw_Volunteers!F11 -> Mobile Unit - Route A | I11: =IF(Raw_Volunteers!G11="",ROUND(AVERAGE(Raw_Volunteers!$G$2:$G$926),1),Raw_Volunteers!G11) -> 3
A12: =Raw_Volunteers!A12 -> V2002 | B12: =IF(COUNTIFS(Raw_Volunteers!$A$2:$A$926,Raw_Volunteers!A12,Raw_Volunteers!$D$2:$D$926,Raw_Volunteers!D12,Raw_Volunteers!$E$2:$E$926,Raw_Volunteers!E12,Raw_Volunteers!$G$2:$G$926,Raw_Volunteers!G12)>1,"Possible Duplicate","") | C12: =Raw_Volunteers!B12 -> D1351-DUP | D12: =IF(C12="","No","Yes") -> Yes | E12: =Raw_Volunteers!C12 -> Kevin Young | F12: =Raw_Volunteers!D12 -> 01/15/2025 | G12: =PROPER(TRIM(Raw_Volunteers!E12)) -> Front Desk Greeter | H12: =Raw_Volunteers!F12 -> Downtown Pantry | I12: =IF(Raw_Volunteers!G12="",ROUND(AVERAGE(Raw_Volunteers!$G$2:$G$926),1),Raw_Volunteers!G12) -> 2
A13: =Raw_Volunteers!A13 -> V2003 | B13: =IF(COUNTIFS(Raw_Volunteers!$A$2:$A$926,Raw_Volunteers!A13,Raw_Volunteers!$D$2:$D$926,Raw_Volunteers!D13,Raw_Volunteers!$E$2:$E$926,Raw_Volunteers!E13,Raw_Volunteers!$G$2:$G$926,Raw_Volunteers!G13)>1,"Possible Duplicate","") | C13: =Raw_Volunteers!B13 -> D1605 | D13: =IF(C13="","No","Yes") -> Yes | E13: =Raw_Volunteers!C13 -> Donald King | F13: =Raw_Volunteers!D13 -> 07/03/2024 | G13: =PROPER(TRIM(Raw_Volunteers!E13)) -> Warehouse Loading | H13: =Raw_Volunteers!F13 -> Mobile Unit - Route A | I13: =IF(Raw_Volunteers!G13="",ROUND(AVERAGE(Raw_Volunteers!$G$2:$G$926),1),Raw_Volunteers!G13) -> 3
... A926: =Raw_Volunteers!A926 -> V2172 | B926: =IF(COUNTIFS(Raw_Volunteers!$A$2:$A$926,Raw_Volunteers!A926,Raw_Volunteers!$D$2:$D$926,Raw_Volunteers!D926,Raw_Volunteers!$E$2:$E$926,Raw_Volunteers!E926,Raw_Volunteers!$G$2:$G$926,Raw_Volunteers!G926)>1,"Possible Duplicate","") -> Possible Duplicate | C926: =Raw_Volunteers!B926 -> 0 | D926: =IF(C926="","No","Yes") -> No | E926: =Raw_Volunteers!C926 -> James Walker | F926: =Raw_Volunteers!D926 -> 04/07/2026 | G926: =PROPER(TRIM(Raw_Volunteers!E926)) -> Event Setup | H926: =Raw_Volunteers!F926 -> Downtown Pantry | I926: =IF(Raw_Volunteers!G926="",ROUND(AVERAGE(Raw_Volunteers!$G$2:$G$926),1),Raw_Volunteers!G926) -> 5

Sheet Donor_Summary
B2: Donor Summary
B4: By Donor Category
B5: Donor Category | C5: Count | D5: % of Total | E5: Total Lifetime Giving | F5: Avg Lifetime Giving
B6: Individual Donor | C6: =COUNTIF(Clean_Donors!G2:G759,B6) -> 509 | D6: =IFERROR(C6/SUM($C$6:$C$8),0) -> 0.67150396 | E6: =SUMIF(Clean_Donors!G2:G759,B6,Clean_Donors!R2:R759) -> 1216864 | F6: =IFERROR(E6/C6,0) -> 2390.6955
B7: Family Donor | C7: =COUNTIF(Clean_Donors!G2:G759,B7) -> 58 | D7: =IFERROR(C7/SUM($C$6:$C$8),0) -> 0.07651715 | E7: =SUMIF(Clean_Donors!G2:G759,B7,Clean_Donors!R2:R759) -> 22624 | F7: =IFERROR(E7/C7,0) -> 390.06897
B8: Community Partner | C8: =COUNTIF(Clean_Donors!G2:G759,B8) -> 191 | D8: =IFERROR(C8/SUM($C$6:$C$8),0) -> 0.25197889 | E8: =SUMIF(Clean_Donors!G2:G759,B8,Clean_Donors!R2:R759) -> 116760 | F8: =IFERROR(E8/C8,0) -> 611.3089
B9: Total | C9: =SUM(C6:C8) -> 758 | D9: =SUM(D6:D8) -> 1 | E9: =SUM(E6:E8) -> 1356248 | F9: =IFERROR(E9/C9,0) -> 1789.2454
B12: By Wealth Rating
B13: Wealth Rating | C13: Donor Count | D13: Total Lifetime Giving
B14: Not Rated | C14: =COUNTIF(Clean_Donors!I2:I759,B14) -> 706 | D14: =SUMIF(Clean_Donors!I2:I759,B14,Clean_Donors!R2:R759) -> 1188705
B15: $1-$24,999 | C15: =COUNTIF(Clean_Donors!I2:I759,B15) -> 7 | D15: =SUMIF(Clean_Donors!I2:I759,B15,Clean_Donors!R2:R759) -> 504
B16: $25,000-$49,999 | C16: =COUNTIF(Clean_Donors!I2:I759,B16) -> 11 | D16: =SUMIF(Clean_Donors!I2:I759,B16,Clean_Donors!R2:R759) -> 1066
B17: $50,000-$99,999 | C17: =COUNTIF(Clean_Donors!I2:I759,B17) -> 11 | D17: =SUMIF(Clean_Donors!I2:I759,B17,Clean_Donors!R2:R759) -> 1844
B18: $100,000-$249,999 | C18: =COUNTIF(Clean_Donors!I2:I759,B18) -> 12 | D18: =SUMIF(Clean_Donors!I2:I759,B18,Clean_Donors!R2:R759) -> 920
B19: $250,000-$499,999 | C19: =COUNTIF(Clean_Donors!I2:I759,B19) -> 8 | D19: =SUMIF(Clean_Donors!I2:I759,B19,Clean_Donors!R2:R759) -> 26522
B20: $500,000-$999,999 | C20: =COUNTIF(Clean_Donors!I2:I759,B20) -> 3 | D20: =SUMIF(Clean_Donors!I2:I759,B20,Clean_Donors!R2:R759) -> 136687
B23: Giving Trend by Fiscal Year
B24: Fiscal Year | C24: Total Given | D24: Number of Gifts (>$0)
B25: FY2021 | C25: =SUM(Clean_Donors!M2:M759) -> 12001 | D25: =COUNTIF(Clean_Donors!M2:M759,">0") -> 54
B26: FY2022 | C26: =SUM(Clean_Donors!N2:N759) -> 188140 | D26: =COUNTIF(Clean_Donors!N2:N759,">0") -> 52
B27: FY2023 | C27: =SUM(Clean_Donors!O2:O759) -> 114344 | D27: =COUNTIF(Clean_Donors!O2:O759,">0") -> 58
B28: FY2024 | C28: =SUM(Clean_Donors!P2:P759) -> 82754 | D28: =COUNTIF(Clean_Donors!P2:P759,">0") -> 68
B29: FY2025 | C29: =SUM(Clean_Donors!Q2:Q759) -> 123424 | D29: =COUNTIF(Clean_Donors!Q2:Q759,">0") -> 48
B32: Data Quality Notes
B33: Metric | C33: Value
B34: Duplicate DonorIDs flagged | C34: =COUNTIF(Clean_Donors!B2:B759,"Duplicate ID") -> 8
B35: Donors missing Wealth Rating | C35: =COUNTIF(Clean_Donors!I2:I759,"Not Rated") -> 706
B36: Donors with no Birth Date on file | C36: =COUNTBLANK(Clean_Donors!T2:T759) -> 477
B37: Lapsed donors flagged for follow-up | C37: =COUNTIF(Clean_Donors!U2:U759,"Lapsed - Follow Up") -> 100

Sheet Engagement_Dashboard
B2: Donor & Volunteer Engagement Dashboard
B4: =COUNTA(Clean_Donors!A2:A759)-COUNTIF(Clean_Donors!B2:B759,"Duplicate ID") -> 750 | D4: =COUNTIF(Clean_Donors!Q2:Q759,">0") -> 48 | F4: =SUMPRODUCT((COUNTIF(Clean_Volunteers!A2:A926,Clean_Volunteers!A2:A926)>0)/COUNTIF(Clean_Volunteers!A2:A926,Clean_Volunteers!A2:A926)) -> 215 | H4: =SUMPRODUCT((Clean_Volunteers!D2:D926="Yes")/COUNTIF(Clean_Volunteers!A2:A926,Clean_Volunteers!A2:A926)) -> 120 | J4: =COUNTIF(Clean_Donors!U2:U759,"Lapsed - Follow Up") -> 100 | L4: =SUM(Clean_Volunteers!I2:I926) -> 2666.2
B6: Total Donors | D6: Active Donors (FY2025) | F6: Unique Volunteers | H6: Donors Who Also Volunteer | J6: Lapsed Donors (Need Follow-up) | L6: Total Volunteer Hours
B9: Top 15 Donors by Lifetime Giving
B10: Rank | C10: DonorID | D10: Donor Category | E10: Total Lifetime Giving | F10: Also Volunteers?
B11: 1 | C11: =IFERROR(INDEX(Clean_Donors!$A$2:$A$759,MATCH(1,Clean_Donors!$V$2:$V$759,0)),"") -> D1087 | D11: =IFERROR(INDEX(Clean_Donors!$G$2:$G$759,MATCH(C11,Clean_Donors!$A$2:$A$759,0)),"") -> Individual Donor | E11: =IFERROR(INDEX(Clean_Donors!$R$2:$R$759,MATCH(C11,Clean_Donors!$A$2:$A$759,0)),0) -> 585400 | F11: =IF(COUNTIF(Clean_Volunteers!$C$2:$C$926,C11)>0,"Yes","No") -> No
B12: 2 | C12: =IFERROR(INDEX(Clean_Donors!$A$2:$A$759,MATCH(2,Clean_Donors!$V$2:$V$759,0)),"") -> D1437 | D12: =IFERROR(INDEX(Clean_Donors!$G$2:$G$759,MATCH(C12,Clean_Donors!$A$2:$A$759,0)),"") -> Individual Donor | E12: =IFERROR(INDEX(Clean_Donors!$R$2:$R$759,MATCH(C12,Clean_Donors!$A$2:$A$759,0)),0) -> 213200 | F12: =IF(COUNTIF(Clean_Volunteers!$C$2:$C$926,C12)>0,"Yes","No") -> No
B13: 3 | C13: =IFERROR(INDEX(Clean_Donors!$A$2:$A$759,MATCH(3,Clean_Donors!$V$2:$V$759,0)),"") -> D1593 | D13: =IFERROR(INDEX(Clean_Donors!$G$2:$G$759,MATCH(C13,Clean_Donors!$A$2:$A$759,0)),"") -> Individual Donor | E13: =IFERROR(INDEX(Clean_Donors!$R$2:$R$759,MATCH(C13,Clean_Donors!$A$2:$A$759,0)),0) -> 126500 | F13: =IF(COUNTIF(Clean_Volunteers!$C$2:$C$926,C13)>0,"Yes","No") -> No
B14: 4 | C14: =IFERROR(INDEX(Clean_Donors!$A$2:$A$759,MATCH(4,Clean_Donors!$V$2:$V$759,0)),"") -> D1589 | D14: =IFERROR(INDEX(Clean_Donors!$G$2:$G$759,MATCH(C14,Clean_Donors!$A$2:$A$759,0)),"") -> Individual Donor | E14: =IFERROR(INDEX(Clean_Donors!$R$2:$R$759,MATCH(C14,Clean_Donors!$A$2:$A$759,0)),0) -> 100000 | F14: =IF(COUNTIF(Clean_Volunteers!$C$2:$C$926,C14)>0,"Yes","No") -> No
B15: 5 | C15: =IFERROR(INDEX(Clean_Donors!$A$2:$A$759,MATCH(5,Clean_Donors!$V$2:$V$759,0)),"") -> D1585 | D15: =IFERROR(INDEX(Clean_Donors!$G$2:$G$759,MATCH(C15,Clean_Donors!$A$2:$A$759,0)),"") -> Community Partner | E15: =IFERROR(INDEX(Clean_Donors!$R$2:$R$759,MATCH(C15,Clean_Donors!$A$2:$A$759,0)),0) -> 76500 | F15: =IF(COUNTIF(Clean_Volunteers!$C$2:$C$926,C15)>0,"Yes","No") -> Yes
B16: 6 | C16: =IFERROR(INDEX(Clean_Donors!$A$2:$A$759,MATCH(6,Clean_Donors!$V$2:$V$759,0)),"") -> D1107 | D16: =IFERROR(INDEX(Clean_Donors!$G$2:$G$759,MATCH(C16,Clean_Donors!$A$2:$A$759,0)),"") -> Individual Donor | E16: =IFERROR(INDEX(Clean_Donors!$R$2:$R$759,MATCH(C16,Clean_Donors!$A$2:$A$759,0)),0) -> 25500 | F16: =IF(COUNTIF(Clean_Volunteers!$C$2:$C$926,C16)>0,"Yes","No") -> No
B17: 7 | C17: =IFERROR(INDEX(Clean_Donors!$A$2:$A$759,MATCH(7,Clean_Donors!$V$2:$V$759,0)),"") -> D1091 | D17: =IFERROR(INDEX(Clean_Donors!$G$2:$G$759,MATCH(C17,Clean_Donors!$A$2:$A$759,0)),"") -> Individual Donor | E17: =IFERROR(INDEX(Clean_Donors!$R$2:$R$759,MATCH(C17,Clean_Donors!$A$2:$A$759,0)),0) -> 11704 | F17: =IF(COUNTIF(Clean_Volunteers!$C$2:$C$926,C17)>0,"Yes","No") -> No
B18: 8 | C18: =IFERROR(INDEX(Clean_Donors!$A$2:$A$759,MATCH(8,Clean_Donors!$V$2:$V$759,0)),"") -> D1689 | D18: =IFERROR(INDEX(Clean_Donors!$G$2:$G$759,MATCH(C18,Clean_Donors!$A$2:$A$759,0)),"") -> Individual Donor | E18: =IFERROR(INDEX(Clean_Donors!$R$2:$R$759,MATCH(C18,Clean_Donors!$A$2:$A$759,0)),0) -> 11077 | F18: =IF(COUNTIF(Clean_Volunteers!$C$2:$C$926,C18)>0,"Yes","No") -> No
B19: 9 | C19: =IFERROR(INDEX(Clean_Donors!$A$2:$A$759,MATCH(9,Clean_Donors!$V$2:$V$759,0)),"") -> D1046 | D19: =IFERROR(INDEX(Clean_Donors!$G$2:$G$759,MATCH(C19,Clean_Donors!$A$2:$A$759,0)),"") -> Family Donor | E19: =IFERROR(INDEX(Clean_Donors!$R$2:$R$759,MATCH(C19,Clean_Donors!$A$2:$A$759,0)),0) -> 10000 | F19: =IF(COUNTIF(Clean_Volunteers!$C$2:$C$926,C19)>0,"Yes","No") -> No
B20: 10 | C20: =IFERROR(INDEX(Clean_Donors!$A$2:$A$759,MATCH(10,Clean_Donors!$V$2:$V$759,0)),"") -> D1552 | D20: =IFERROR(INDEX(Clean_Donors!$G$2:$G$759,MATCH(C20,Clean_Donors!$A$2:$A$759,0)),"") -> Individual Donor | E20: =IFERROR(INDEX(Clean_Donors!$R$2:$R$759,MATCH(C20,Clean_Donors!$A$2:$A$759,0)),0) -> 9155 | F20: =IF(COUNTIF(Clean_Volunteers!$C$2:$C$926,C20)>0,"Yes","No") -> Yes
B21: 11 | C21: =IFERROR(INDEX(Clean_Donors!$A$2:$A$759,MATCH(11,Clean_Donors!$V$2:$V$759,0)),"") -> D1284 | D21: =IFERROR(INDEX(Clean_Donors!$G$2:$G$759,MATCH(C21,Clean_Donors!$A$2:$A$759,0)),"") -> Individual Donor | E21: =IFERROR(INDEX(Clean_Donors!$R$2:$R$759,MATCH(C21,Clean_Donors!$A$2:$A$759,0)),0) -> 8772 | F21: =IF(COUNTIF(Clean_Volunteers!$C$2:$C$926,C21)>0,"Yes","No") -> No
B22: 12 | C22: =IFERROR(INDEX(Clean_Donors!$A$2:$A$759,MATCH(12,Clean_Donors!$V$2:$V$759,0)),"") -> D1723 | D22: =IFERROR(INDEX(Clean_Donors!$G$2:$G$759,MATCH(C22,Clean_Donors!$A$2:$A$759,0)),"") -> Individual Donor | E22: =IFERROR(INDEX(Clean_Donors!$R$2:$R$759,MATCH(C22,Clean_Donors!$A$2:$A$759,0)),0) -> 5255 | F22: =IF(COUNTIF(Clean_Volunteers!$C$2:$C$926,C22)>0,"Yes","No") -> Yes
B23: 13 | C23: =IFERROR(INDEX(Clean_Donors!$A$2:$A$759,MATCH(13,Clean_Donors!$V$2:$V$759,0)),"") -> D1208 | D23: =IFERROR(INDEX(Clean_Donors!$G$2:$G$759,MATCH(C23,Clean_Donors!$A$2:$A$759,0)),"") -> Individual Donor | E23: =IFERROR(INDEX(Clean_Donors!$R$2:$R$759,MATCH(C23,Clean_Donors!$A$2:$A$759,0)),0) -> 5000 | F23: =IF(COUNTIF(Clean_Volunteers!$C$2:$C$926,C23)>0,"Yes","No") -> Yes
B24: 14 | C24: =IFERROR(INDEX(Clean_Donors!$A$2:$A$759,MATCH(14,Clean_Donors!$V$2:$V$759,0)),"") -> D1225 | D24: =IFERROR(INDEX(Clean_Donors!$G$2:$G$759,MATCH(C24,Clean_Donors!$A$2:$A$759,0)),"") -> Individual Donor | E24: =IFERROR(INDEX(Clean_Donors!$R$2:$R$759,MATCH(C24,Clean_Donors!$A$2:$A$759,0)),0) -> 5000 | F24: =IF(COUNTIF(Clean_Volunteers!$C$2:$C$926,C24)>0,"Yes","No") -> No
B25: 15 | C25: =IFERROR(INDEX(Clean_Donors!$A$2:$A$759,MATCH(15,Clean_Donors!$V$2:$V$759,0)),"") -> D1236 | D25: =IFERROR(INDEX(Clean_Donors!$G$2:$G$759,MATCH(C25,Clean_Donors!$A$2:$A$759,0)),"") -> Community Partner | E25: =IFERROR(INDEX(Clean_Donors!$R$2:$R$759,MATCH(C25,Clean_Donors!$A$2:$A$759,0)),0) -> 4270 | F25: =IF(COUNTIF(Clean_Volunteers!$C$2:$C$926,C25)>0,"Yes","No") -> Yes
B28: Lapsed Donors — Priority Follow-Up List (sample of flagged donors)
B29: DonorID | C29: Donor Category | D29: FY2023 Gift | E29: FY2024 Gift | F29: FY2025 Gift | G29: Consecutive Years Giving (prior)
B30: =IFERROR(INDEX(Clean_Donors!$A$2:$A$759,MATCH(1,Clean_Donors!$W$2:$W$759,0)),"") -> D1014 | C30: =IFERROR(INDEX(Clean_Donors!$G$2:$G$759,MATCH(B30,Clean_Donors!$A$2:$A$759,0)),"") -> Community Partner | D30: =IFERROR(INDEX(Clean_Donors!$O$2:$O$759,MATCH(B30,Clean_Donors!$A$2:$A$759,0)),0) -> 0 | E30: =IFERROR(INDEX(Clean_Donors!$P$2:$P$759,MATCH(B30,Clean_Donors!$A$2:$A$759,0)),0) -> 25 | F30: =IFERROR(INDEX(Clean_Donors!$Q$2:$Q$759,MATCH(B30,Clean_Donors!$A$2:$A$759,0)),0) -> 0 | G30: =IFERROR(INDEX(Clean_Donors!$L$2:$L$759,MATCH(B30,Clean_Donors!$A$2:$A$759,0)),0) -> 1
B31: =IFERROR(INDEX(Clean_Donors!$A$2:$A$759,MATCH(2,Clean_Donors!$W$2:$W$759,0)),"") -> D1021 | C31: =IFERROR(INDEX(Clean_Donors!$G$2:$G$759,MATCH(B31,Clean_Donors!$A$2:$A$759,0)),"") -> Individual Donor | D31: =IFERROR(INDEX(Clean_Donors!$O$2:$O$759,MATCH(B31,Clean_Donors!$A$2:$A$759,0)),0) -> 136 | E31: =IFERROR(INDEX(Clean_Donors!$P$2:$P$759,MATCH(B31,Clean_Donors!$A$2:$A$759,0)),0) -> 200 | F31: =IFERROR(INDEX(Clean_Donors!$Q$2:$Q$759,MATCH(B31,Clean_Donors!$A$2:$A$759,0)),0) -> 0 | G31: =IFERROR(INDEX(Clean_Donors!$L$2:$L$759,MATCH(B31,Clean_Donors!$A$2:$A$759,0)),0) -> 1
B32: =IFERROR(INDEX(Clean_Donors!$A$2:$A$759,MATCH(3,Clean_Donors!$W$2:$W$759,0)),"") -> D1022 | C32: =IFERROR(INDEX(Clean_Donors!$G$2:$G$759,MATCH(B32,Clean_Donors!$A$2:$A$759,0)),"") -> Individual Donor | D32: =IFERROR(INDEX(Clean_Donors!$O$2:$O$759,MATCH(B32,Clean_Donors!$A$2:$A$759,0)),0) -> 1 | E32: =IFERROR(INDEX(Clean_Donors!$P$2:$P$759,MATCH(B32,Clean_Donors!$A$2:$A$759,0)),0) -> 251 | F32: =IFERROR(INDEX(Clean_Donors!$Q$2:$Q$759,MATCH(B32,Clean_Donors!$A$2:$A$759,0)),0) -> 0 | G32: =IFERROR(INDEX(Clean_Donors!$L$2:$L$759,MATCH(B32,Clean_Donors!$A$2:$A$759,0)),0) -> 1
B33: =IFERROR(INDEX(Clean_Donors!$A$2:$A$759,MATCH(4,Clean_Donors!$W$2:$W$759,0)),"") -> D1023 | C33: =IFERROR(INDEX(Clean_Donors!$G$2:$G$759,MATCH(B33,Clean_Donors!$A$2:$A$759,0)),"") -> Individual Donor | D33: =IFERROR(INDEX(Clean_Donors!$O$2:$O$759,MATCH(B33,Clean_Donors!$A$2:$A$759,0)),0) -> 1 | E33: =IFERROR(INDEX(Clean_Donors!$P$2:$P$759,MATCH(B33,Clean_Donors!$A$2:$A$759,0)),0) -> 0 | F33: =IFERROR(INDEX(Clean_Donors!$Q$2:$Q$759,MATCH(B33,Clean_Donors!$A$2:$A$759,0)),0) -> 0 | G33: =IFERROR(INDEX(Clean_Donors!$L$2:$L$759,MATCH(B33,Clean_Donors!$A$2:$A$759,0)),0) -> 1
B34: =IFERROR(INDEX(Clean_Donors!$A$2:$A$759,MATCH(5,Clean_Donors!$W$2:$W$759,0)),"") -> D1027 | C34: =IFERROR(INDEX(Clean_Donors!$G$2:$G$759,MATCH(B34,Clean_Donors!$A$2:$A$759,0)),"") -> Individual Donor | D34: =IFERROR(INDEX(Clean_Donors!$O$2:$O$759,MATCH(B34,Clean_Donors!$A$2:$A$759,0)),0) -> 300 | E34: =IFERROR(INDEX(Clean_Donors!$P$2:$P$759,MATCH(B34,Clean_Donors!$A$2:$A$759,0)),0) -> 0 | F34: =IFERROR(INDEX(Clean_Donors!$Q$2:$Q$759,MATCH(B34,Clean_Donors!$A$2:$A$759,0)),0) -> 0 | G34: =IFERROR(INDEX(Clean_Donors!$L$2:$L$759,MATCH(B34,Clean_Donors!$A$2:$A$759,0)),0) -> 1
B35: =IFERROR(INDEX(Clean_Donors!$A$2:$A$759,MATCH(6,Clean_Donors!$W$2:$W$759,0)),"") -> D1035 | C35: =IFERROR(INDEX(Clean_Donors!$G$2:$G$759,MATCH(B35,Clean_Donors!$A$2:$A$759,0)),"") -> Individual Donor | D35: =IFERROR(INDEX(Clean_Donors!$O$2:$O$759,MATCH(B35,Clean_Donors!$A$2:$A$759,0)),0) -> 0 | E35: =IFERROR(INDEX(Clean_Donors!$P$2:$P$759,MATCH(B35,Clean_Donors!$A$2:$A$759,0)),0) -> 1 | F35: =IFERROR(INDEX(Clean_Donors!$Q$2:$Q$759,MATCH(B35,Clean_Donors!$A$2:$A$759,0)),0) -> 0 | G35: =IFERROR(INDEX(Clean_Donors!$L$2:$L$759,MATCH(B35,Clean_Donors!$A$2:$A$759,0)),0) -> 1
B36: =IFERROR(INDEX(Clean_Donors!$A$2:$A$759,MATCH(7,Clean_Donors!$W$2:$W$759,0)),"") -> D1039 | C36: =IFERROR(INDEX(Clean_Donors!$G$2:$G$759,MATCH(B36,Clean_Donors!$A$2:$A$759,0)),"") -> Individual Donor | D36: =IFERROR(INDEX(Clean_Donors!$O$2:$O$759,MATCH(B36,Clean_Donors!$A$2:$A$759,0)),0) -> 0 | E36: =IFERROR(INDEX(Clean_Donors!$P$2:$P$759,MATCH(B36,Clean_Donors!$A$2:$A$759,0)),0) -> 1 | F36: =IFERROR(INDEX(Clean_Donors!$Q$2:$Q$759,MATCH(B36,Clean_Donors!$A$2:$A$759,0)),0) -> 0 | G36: =IFERROR(INDEX(Clean_Donors!$L$2:$L$759,MATCH(B36,Clean_Donors!$A$2:$A$759,0)),0) -> 0
B37: =IFERROR(INDEX(Clean_Donors!$A$2:$A$759,MATCH(8,Clean_Donors!$W$2:$W$759,0)),"") -> D1044 | C37: =IFERROR(INDEX(Clean_Donors!$G$2:$G$759,MATCH(B37,Clean_Donors!$A$2:$A$759,0)),"") -> Community Partner | D37: =IFERROR(INDEX(Clean_Donors!$O$2:$O$759,MATCH(B37,Clean_Donors!$A$2:$A$759,0)),0) -> 0 | E37: =IFERROR(INDEX(Clean_Donors!$P$2:$P$759,MATCH(B37,Clean_Donors!$A$2:$A$759,0)),0) -> 80 | F37: =IFERROR(INDEX(Clean_Donors!$Q$2:$Q$759,MATCH(B37,Clean_Donors!$A$2:$A$759,0)),0) -> 0 | G37: =IFERROR(INDEX(Clean_Donors!$L$2:$L$759,MATCH(B37,Clean_Donors!$A$2:$A$759,0)),0) -> 0
B38: =IFERROR(INDEX(Clean_Donors!$A$2:$A$759,MATCH(9,Clean_Donors!$W$2:$W$759,0)),"") -> D1046 | C38: =IFERROR(INDEX(Clean_Donors!$G$2:$G$759,MATCH(B38,Clean_Donors!$A$2:$A$759,0)),"") -> Family Donor | D38: =IFERROR(INDEX(Clean_Donors!$O$2:$O$759,MATCH(B38,Clean_Donors!$A$2:$A$759,0)),0) -> 10000 | E38: =IFERROR(INDEX(Clean_Donors!$P$2:$P$759,MATCH(B38,Clean_Donors!$A$2:$A$759,0)),0) -> 0 | F38: =IFERROR(INDEX(Clean_Donors!$Q$2:$Q$759,MATCH(B38,Clean_Donors!$A$2:$A$759,0)),0) -> 0 | G38: =IFERROR(INDEX(Clean_Donors!$L$2:$L$759,MATCH(B38,Clean_Donors!$A$2:$A$759,0)),0) -> 1
B39: =IFERROR(INDEX(Clean_Donors!$A$2:$A$759,MATCH(10,Clean_Donors!$W$2:$W$759,0)),"") -> D1047 | C39: =IFERROR(INDEX(Clean_Donors!$G$2:$G$759,MATCH(B39,Clean_Donors!$A$2:$A$759,0)),"") -> Individual Donor | D39: =IFERROR(INDEX(Clean_Donors!$O$2:$O$759,MATCH(B39,Clean_Donors!$A$2:$A$759,0)),0) -> 0 | E39: =IFERROR(INDEX(Clean_Donors!$P$2:$P$759,MATCH(B39,Clean_Donors!$A$2:$A$759,0)),0) -> 1000 | F39: =IFERROR(INDEX(Clean_Donors!$Q$2:$Q$759,MATCH(B39,Clean_Donors!$A$2:$A$759,0)),0) -> 0 | G39: =IFERROR(INDEX(Clean_Donors!$L$2:$L$759,MATCH(B39,Clean_Donors!$A$2:$A$759,0)),0) -> 3
B40: =IFERROR(INDEX(Clean_Donors!$A$2:$A$759,MATCH(11,Clean_Donors!$W$2:$W$759,0)),"") -> D1052 | C40: =IFERROR(INDEX(Clean_Donors!$G$2:$G$759,MATCH(B40,Clean_Donors!$A$2:$A$759,0)),"") -> Community Partner | D40: =IFERROR(INDEX(Clean_Donors!$O$2:$O$759,MATCH(B40,Clean_Donors!$A$2:$A$759,0)),0) -> 90 | E40: =IFERROR(INDEX(Clean_Donors!$P$2:$P$759,MATCH(B40,Clean_Donors!$A$2:$A$759,0)),0) -> 90 | F40: =IFERROR(INDEX(Clean_Donors!$Q$2:$Q$759,MATCH(B40,Clean_Donors!$A$2:$A$759,0)),0) -> 0 | G40: =IFERROR(INDEX(Clean_Donors!$L$2:$L$759,MATCH(B40,Clean_Donors!$A$2:$A$759,0)),0) -> 1
